Workbook

Sheet How to update
A1: Labour Market Statistics Briefing — April 2026
A3: HOW TO UPDATE THIS WORKBOOK
A4: ----------------------------
A5: This workbook is auto-generated from ONS source datasets.
A6: To update, download the latest files from ONS and upload them via the app.
A8: Required: A01, HR1, X09, RTISA
A9: Optional: CLA01, X02, OECD (3 files)
A11: LFS period: Dec-Feb 2026
A12: Comparison periods: vs Sep-Nov 2025 | vs Dec-Feb 2025 | vs Dec-Feb 2020 | vs Apr-Jun 2024

Sheet Data links
A1: Sheet | B1: Source
A2: 1. Payrolled employees (UK) | B2: RTISA
A3: 23. Employees Industry | B3: RTISA
A4: 2 | B4: A01
A5: 5 | B5: A01
A6: 10 | B6: A01
A7: 11 | B7: A01
A8: 13 | B8: A01
A9: 15 | B9: A01
A10: 18 | B10: A01
A11: 19 | B11: A01
A12: 20 | B12: A01
... A21: Regional breakdowns | B21: A01

Sheet Dashboard
B1: Labour Market Dashboard — April 2026
B2: LFS period: Dec-Feb 2026
B5: Key Metrics | D5: Current | E5: Change on quarter | F5: Change on year | G5: Change since Covid | H5: Change since election
B6: Employment (000s) 16+ | D6: ='2'!B5 | E6: ='2'!B6 | F6: ='2'!B7 | G6: ='2'!B8 | H6: ='2'!B10
B7: Employment rate (16-64) | D7: ='2'!K5/100 | E7: ='2'!K6 | F7: ='2'!K7 | G7: ='2'!K8 | H7: ='2'!K10
B8: Unemployment, 16+ (000s) | D8: ='2'!D5 | E8: ='2'!D6 | F8: ='2'!D7 | G8: ='2'!D8 | H8: ='2'!D10
B9: Unemployment rate, 16+ | D9: ='2'!E5/100 | E9: ='2'!E6 | F9: ='2'!E7 | G9: ='2'!E8 | H9: ='2'!E10
B10: Economic inactivity (000s) (16-64) | D10: ='2'!P5 | E10: ='2'!P6 | F10: ='2'!P7 | G10: ='2'!P8 | H10: ='2'!P10
B11: Economic inactivity rate (16-64) | D11: ='2'!Q5/100 | E11: ='2'!Q6 | F11: ='2'!Q7 | G11: ='2'!Q8 | H11: ='2'!Q10
B12: 50-64s inactivity (000s) | D12: ='2'!BD5 | E12: ='2'!BD6 | F12: ='2'!BD7 | G12: ='2'!BD8 | H12: ='2'!BD10
B13: 50-64s inactivity rate | D13: ='2'!BE5/100 | E13: ='2'!BE6 | F13: ='2'!BE7 | G13: ='2'!BE8 | H13: ='2'!BE10
B14: Payrolled employees (000s) | D14: ='1. Payrolled employees (UK)'!B2 | E14: ='1. Payrolled employees (UK)'!D2 | F14: ='1. Payrolled employees (UK)'!E2 | G14: ='1. Payrolled employees (UK)'!G2 | H14: ='1. Payrolled employees (UK)'!H2
B15: Vacancies (000s) | D15: ='20'!B2 | E15: ='20'!B3 | F15: ='20'!B4 | G15: ='20'!B5 | H15: ='20'!B6
B16: Wage growth, total pay (yearly %) | D16: ='13'!D4/100 | E16: ='13'!D5 | F16: ='13'!D6 | G16: ='13'!D7 | H16: ='13'!D8
B17: Wage growth, CPI-adjusted (yearly %) | D17: ='AWE Real_CPI'!C2/100 | E17: ='AWE Real_CPI'!C3 | F17: ='AWE Real_CPI'!C4 | G17: ='AWE Real_CPI'!C5 | H17: ='AWE Real_CPI'!C8

Sheet 1. Payrolled employees (UK)
B1: Current | C1: Change on month (singular) | D1: Change on quarter | E1: Change year on year (3 month average) | F1: Change year on year (singular) | G1: Change since Covid-19 | H1: Change since 2024 election | I1: Change since coming into office | J1: Change since start of the year | K1: Max
A2: Number | B2: =AVERAGE(OFFSET(INDEX($B$11:$B$1048576,COUNT($B$11:$B$1048576)),-2,0,3,1)) | C2: =INDEX($B$11:$B$1048576,COUNT($B$11:$B$1048576))-INDEX($B$11:$B$1048576,COUNT($B$11:$B$1048576)-1) | D2: =AVERAGE(OFFSET(INDEX($B$11:$B$1048576,COUNT($B$11:$B$1048576)),-2,0,3,1))-AVERAGE(OFFSET(INDEX($B$11:$B$1048576,COUNT($B$11:$B$1048576)),-5,0,3,1)) | E2: =AVERAGE(OFFSET(INDEX($B$11:$B$1048576,COUNT($B$11:$B$1048576)),-2,0,3,1))-AVERAGE(OFFSET(INDEX($B$11:$B$1048576,COUNT($B$11:$B$1048576)),-14,0,3,1)) | F2: =INDEX($B$11:$B$1048576,COUNT($B$11:$B$1048576))-INDEX($B$11:$B$1048576,COUNT($B$11:$B$1048576)-12) | G2: =AVERAGE(OFFSET(INDEX($B$11:$B$1048576,COUNT($B$11:$B$1048576)),-2,0,3,1))-AVERAGE($B$76:$B$78) | H2: =AVERAGE(OFFSET(INDEX($B$11:$B$1048576,COUNT($B$11:$B$1048576)),-2,0,3,1))-AVERAGE($B$128:$B$130) | I2: =INDEX($B$11:$B$1048576,COUNT($B$11:$B$1048576))-$B$130 | J2: =INDEX(B$11:B$1048576,COUNT(B$11:B$1048576))-_xlfn.XLOOKUP("January "&TEXT(TODAY(),"yyyy"),A$11:A$1048576,B$11:B$1048576) | K2: =MAX($B$11:$B$1048576)
A3: % | C3: =IFERROR(INDEX($B$11:$B$1048576,COUNT($B$11:$B$1048576))/INDEX($B$11:$B$1048576,COUNT($B$11:$B$1048576)-1)-1,"") | D3: =IFERROR(AVERAGE(OFFSET(INDEX($B$11:$B$1048576,COUNT($B$11:$B$1048576)),-2,0,3,1))/AVERAGE(OFFSET(INDEX($B$11:$B$1048576,COUNT($B$11:$B$1048576)),-5,0,3,1))-1,"") | E3: =IFERROR(AVERAGE(OFFSET(INDEX($B$11:$B$1048576,COUNT($B$11:$B$1048576)),-2,0,3,1))/AVERAGE(OFFSET(INDEX($B$11:$B$1048576,COUNT($B$11:$B$1048576)),-14,0,3,1))-1,"") | F3: =IFERROR(INDEX($B$11:$B$1048576,COUNT($B$11:$B$1048576))/INDEX($B$11:$B$1048576,COUNT($B$11:$B$1048576)-12)-1,"") | G3: =IFERROR(INDEX($B$11:$B$1048576,COUNT($B$11:$B$1048576))/AVERAGE($B$76:$B$78)-1,"") | H3: =IFERROR(AVERAGE(OFFSET(INDEX($B$11:$B$1048576,COUNT($B$11:$B$1048576)),-2,0,3,1))/AVERAGE($B$128:$B$130)-1,"") | I3: =IFERROR(INDEX($B$11:$B$1048576,COUNT($B$11:$B$1048576))/$B$130-1,"") | J3: =IFERROR(INDEX(B$11:B$1048576,COUNT(B$11:B$1048576))/_xlfn.XLOOKUP("January "&TEXT(TODAY(),"yyyy"),A$11:A$1048576,B$11:B$1048576)-1,"")
A5: 1. Payrolled employee counts from PAYE RTI
A6: UK, all industries, seasonally adjusted
A8: Units | B8: Payrolled employees
A10: Date | B10: Payrolled employees | C10: Change on previous month
A11: July 2014 | B11: 26762070
A12: August 2014 | B12: 26837205 | C12: 75135
A13: September 2014 | B13: 26892054 | C13: 54849
A14: October 2014 | B14: 26906086 | C14: 14032
A15: November 2014 | B15: 27001141 | C15: 95055
A16: December 2014 | B16: 26998102 | C16: -3039
A17: January 2015 | B17: 27157666 | C17: 159564
A18: February 2015 | B18: 27214594 | C18: 56928
A19: March 2015 | B19: 27294638 | C19: 80044
A20: April 2015 | B20: 27340711 | C20: 46073
A21: May 2015 | B21: 27398943 | C21: 58232
A22: June 2015 | B22: 27461266 | C22: 62323
A23: July 2015 | B23: 27519220 | C23: 57954
... A151: March 2026 | B151: 30313223 | C151: -10998

Sheet 23. Employees Industry
A1: Yearly change
A2: Number | B2: =INDEX(B$12:B$1048576,COUNT(B$12:B$1048576))-INDEX(B$12:B$1048576,COUNT(B$12:B$1048576)-12) | C2: =INDEX(C$12:C$1048576,COUNT(C$12:C$1048576))-INDEX(C$12:C$1048576,COUNT(C$12:C$1048576)-12) | D2: =INDEX(D$12:D$1048576,COUNT(D$12:D$1048576))-INDEX(D$12:D$1048576,COUNT(D$12:D$1048576)-12) | E2: =INDEX(E$12:E$1048576,COUNT(E$12:E$1048576))-INDEX(E$12:E$1048576,COUNT(E$12:E$1048576)-12) | F2: =INDEX(F$12:F$1048576,COUNT(F$12:F$1048576))-INDEX(F$12:F$1048576,COUNT(F$12:F$1048576)-12) | G2: =INDEX(G$12:G$1048576,COUNT(G$12:G$1048576))-INDEX(G$12:G$1048576,COUNT(G$12:G$1048576)-12) | H2: =INDEX(H$12:H$1048576,COUNT(H$12:H$1048576))-INDEX(H$12:H$1048576,COUNT(H$12:H$1048576)-12) | I2: =INDEX(I$12:I$1048576,COUNT(I$12:I$1048576))-INDEX(I$12:I$1048576,COUNT(I$12:I$1048576)-12) | ... U2: =INDEX(U$12:U$1048576,COUNT(U$12:U$1048576))-INDEX(U$12:U$1048576,COUNT(U$12:U$1048576)-12)
A3: % | B3: =IFERROR(INDEX(B$12:B$1048576,COUNT(B$12:B$1048576))/INDEX(B$12:B$1048576,COUNT(B$12:B$1048576)-12)-1,"") | C3: =IFERROR(INDEX(C$12:C$1048576,COUNT(C$12:C$1048576))/INDEX(C$12:C$1048576,COUNT(C$12:C$1048576)-12)-1,"") | D3: =IFERROR(INDEX(D$12:D$1048576,COUNT(D$12:D$1048576))/INDEX(D$12:D$1048576,COUNT(D$12:D$1048576)-12)-1,"") | E3: =IFERROR(INDEX(E$12:E$1048576,COUNT(E$12:E$1048576))/INDEX(E$12:E$1048576,COUNT(E$12:E$1048576)-12)-1,"") | F3: =IFERROR(INDEX(F$12:F$1048576,COUNT(F$12:F$1048576))/INDEX(F$12:F$1048576,COUNT(F$12:F$1048576)-12)-1,"") | G3: =IFERROR(INDEX(G$12:G$1048576,COUNT(G$12:G$1048576))/INDEX(G$12:G$1048576,COUNT(G$12:G$1048576)-12)-1,"") | H3: =IFERROR(INDEX(H$12:H$1048576,COUNT(H$12:H$1048576))/INDEX(H$12:H$1048576,COUNT(H$12:H$1048576)-12)-1,"") | I3: =IFERROR(INDEX(I$12:I$1048576,COUNT(I$12:I$1048576))/INDEX(I$12:I$1048576,COUNT(I$12:I$1048576)-12)-1,"") | ... U3: =IFERROR(INDEX(U$12:U$1048576,COUNT(U$12:U$1048576))/INDEX(U$12:U$1048576,COUNT(U$12:U$1048576)-12)-1,"")
A4: Rank | B4: =RANK(B2,$B$2:$U$2) | C4: =RANK(C2,$B$2:$U$2) | D4: =RANK(D2,$B$2:$U$2) | E4: =RANK(E2,$B$2:$U$2) | F4: =RANK(F2,$B$2:$U$2) | G4: =RANK(G2,$B$2:$U$2) | H4: =RANK(H2,$B$2:$U$2) | I4: =RANK(I2,$B$2:$U$2) | ... U4: =RANK(U2,$B$2:$U$2)
A5: 23. Payrolled employees from PAYE RTI
A6: UK, seasonally adjusted
A8: Units | B8: Payrolled employees
B10: A | C10: B | D10: C | E10: D | F10: E | G10: F | H10: G | I10: H | J10: I | K10: J | L10: K | M10: L | N10: M | O10: N | P10: O | Q10: P | R10: Q | S10: R | T10: S | U10: T-U
A11: Date | B11: Agriculture, forestry and fishing | C11: Mining and quarrying | D11: Manufacturing | E11: Energy production and supply | F11: Water supply, sewerage and waste | G11: Construction | H11: Wholesale and retail; repair of motor vehicles | I11: Transportation and storage | J11: Accommodation and food service activities | K11: Information and communication | L11: Finance and insurance | M11: Real estate | N11: Professional, scientific and technical | O11: Administrative and support services | P11: Public administration and defence; social security | Q11: Education | R11: Health and social work | S11: Arts, entertainment and recreation | T11: Other service activities | U11: Households and Extraterritorial | V11: UK
A12: July 2014 | B12: 177905 | C12: 58306 | D12: 2336052 | E12: 92938 | F12: 155653 | G12: 1081413 | H12: 4255550 | I12: 1164524 | J12: 1758754 | K12: 1060891 | L12: 1054669 | M12: 401252 | N12: 1934872 | O12: 2230091 | P12: 1588026 | Q12: 2879238 | R12: 3429041 | S12: 520159 | T12: 486201 | U12: 96537 | V12: 26762070
A13: August 2014 | B13: 178180 | C13: 58484 | D13: 2340517 | E13: 92979 | F13: 155943 | G13: 1087982 | H13: 4264829 | I13: 1166001 | J13: 1767021 | K13: 1066648 | L13: 1055799 | M13: 401901 | N13: 1943607 | O13: 2250287 | P13: 1584799 | Q13: 2881483 | R13: 3435588 | S13: 521090 | T13: 487130 | U13: 96936 | V13: 26837205
A14: September 2014 | B14: 177494 | C14: 58691 | D14: 2346052 | E14: 92856 | F14: 156176 | G14: 1093234 | H14: 4271408 | I14: 1169428 | J14: 1775329 | K14: 1069863 | L14: 1057120 | M14: 402426 | N14: 1950602 | O14: 2247564 | P14: 1583928 | Q14: 2894225 | R14: 3438541 | S14: 521052 | T14: 488579 | U14: 97489 | V14: 26892054
A15: October 2014 | B15: 176018 | C15: 58672 | D15: 2347340 | E15: 92877 | F15: 156254 | G15: 1097390 | H15: 4272943 | I15: 1168761 | J15: 1779285 | K15: 1071191 | L15: 1056135 | M15: 402328 | N15: 1957514 | O15: 2250075 | P15: 1578416 | Q15: 2891538 | R15: 3438165 | S15: 523608 | T15: 489880 | U15: 97697 | V15: 26906086
A16: November 2014 | B16: 177004 | C16: 58747 | D16: 2355053 | E16: 93184 | F16: 156820 | G16: 1104607 | H16: 4289884 | I16: 1173417 | J16: 1789604 | K16: 1075712 | L16: 1058116 | M16: 403231 | N16: 1968668 | O16: 2259129 | P16: 1578001 | Q16: 2895543 | R16: 3448233 | S16: 526446 | T16: 491728 | U16: 98014 | V16: 27001141
A17: December 2014 | B17: 178028 | C17: 58380 | D17: 2317793 | E17: 93448 | F17: 156531 | G17: 1084437 | H17: 4307031 | I17: 1176343 | J17: 1794010 | K17: 1079437 | L17: 1058436 | M17: 403684 | N17: 1973514 | O17: 2266342 | P17: 1575786 | Q17: 2898726 | R17: 3456590 | S17: 528658 | T17: 492349 | U17: 98579 | V17: 26998102
A18: January 2015 | B18: 178600 | C18: 58457 | D18: 2359234 | E18: 93627 | F18: 157925 | G18: 1117642 | H18: 4325826 | I18: 1183725 | J18: 1805841 | K18: 1083137 | L18: 1060570 | M18: 405181 | N18: 1980780 | O18: 2279872 | P18: 1573698 | Q18: 2901637 | R18: 3468005 | S18: 530458 | T18: 494310 | U18: 99141 | V18: 27157666
A19: February 2015 | B19: 178624 | C19: 57879 | D19: 2364860 | E19: 93783 | F19: 158503 | G19: 1119841 | H19: 4335869 | I19: 1187744 | J19: 1807212 | K19: 1089447 | L19: 1061208 | M19: 405418 | N19: 1992971 | O19: 2288608 | P19: 1569119 | Q19: 2901214 | R19: 3474682 | S19: 532886 | T19: 495252 | U19: 99475 | V19: 27214594
A20: March 2015 | B20: 178988 | C20: 57635 | D20: 2367783 | E20: 94098 | F20: 158989 | G20: 1126159 | H20: 4347775 | I20: 1191463 | J20: 1815664 | K20: 1095629 | L20: 1062995 | M20: 406725 | N20: 2007943 | O20: 2301189 | P20: 1565262 | Q20: 2903134 | R20: 3482036 | S20: 534449 | T20: 496799 | U20: 99923 | V20: 27294638
A21: April 2015 | B21: 179860 | C21: 55899 | D21: 2370415 | E21: 92724 | F21: 158858 | G21: 1132000 | H21: 4341305 | I21: 1189292 | J21: 1829415 | K21: 1095865 | L21: 1074648 | M21: 408259 | N21: 2020572 | O21: 2292370 | P21: 1563199 | Q21: 2904130 | R21: 3497750 | S21: 535839 | T21: 497825 | U21: 100485 | V21: 27340711
A22: May 2015 | B22: 180608 | C22: 55444 | D22: 2370526 | E22: 93200 | F22: 159167 | G22: 1136822 | H22: 4351429 | I22: 1192338 | J22: 1838830 | K22: 1099677 | L22: 1075094 | M22: 408925 | N22: 2027850 | O22: 2295493 | P22: 1569714 | Q22: 2900554 | R22: 3504924 | S22: 538603 | T22: 498651 | U22: 101093 | V22: 27398943
A23: June 2015 | B23: 181682 | C23: 54873 | D23: 2375653 | E23: 93848 | F23: 160026 | G23: 1143864 | H23: 4365770 | I23: 1198259 | J23: 1850135 | K23: 1105706 | L23: 1079138 | M23: 410609 | N23: 2037615 | O23: 2293713 | P23: 1548741 | Q23: 2903586 | R23: 3517911 | S23: 541967 | T23: 499528 | U23: 98640 | V23: 27461266
... A152: March 2026 | B152: 196326 | C152: 42797 | D152: 2293599 | E152: 122175 | F152: 214160 | G152: 1335085 | H152: 4247591 | I152: 1410806 | J152: 2130040 | K152: 1253910 | L152: 1113420 | M152: 478212 | N152: 2474486 | O152: 2395366 | P152: 1597090 | Q152: 3175642 | R152: 4522066 | S152: 647452 | T152: 547925 | U152: 115075 | V152: 30313223

Sheet 2
A1: LFS: Employment, unemployment and inactivity by age group
B2: Aged 16 and over | J2: Aged 16-64 | R2: Aged 16-17 | Z2: Aged 18-24 | AH2: Aged 25-34 | AP2: Aged 35-49 | AX2: Aged 50-64
B3: Employment | D3: Unemployment | F3: Activity | H3: Inactivity | J3: Employment | L3: Unemployment | N3: Activity | P3: Inactivity | R3: Employment | T3: Unemployment | V3: Activity | X3: Inactivity | Z3: Employment | AB3: Unemployment | AD3: Activity | AF3: Inactivity | AH3: Employment | AJ3: Unemployment | AL3: Activity | AN3: Inactivity | AP3: Employment | AR3: Unemployment | AT3: Activity | AV3: Inactivity | AX3: Employment | AZ3: Unemployment | BB3: Activity | BD3: Inactivity
B4: level | C4: rate (%) | D4: level | E4: rate (%) | F4: level | G4: rate (%) | H4: level | I4: rate (%) | J4: level | K4: rate (%) | L4: level | M4: rate (%) | N4: level | O4: rate (%) | P4: level | Q4: rate (%) | R4: level | S4: rate (%) | T4: level | U4: rate (%) | V4: level | W4: rate (%) | X4: level | Y4: rate (%) | Z4: level | AA4: rate (%) | AB4: level | AC4: rate (%) | AD4: level | AE4: rate (%) | AF4: level | AG4: rate (%) | AH4: level | AI4: rate (%) | AJ4: level | AK4: rate (%) | AL4: level | AM4: rate (%) | AN4: level | AO4: rate (%) | AP4: level | AQ4: rate (%) | AR4: level | AS4: rate (%) | AT4: level | AU4: rate (%) | AV4: level | AW4: rate (%) | AX4: level | AY4: rate (%) | AZ4: level | BA4: rate (%) | BB4: level | BC4: rate (%) | BD4: level | BE4: rate (%) | BF4: level | BG4: rate (%) | BH4: level | BI4: rate (%) | BJ4: level | BK4: rate (%) | BL4: level | BM4: rate (%)
A5: Current | B5: =INDEX(B$19:B$1048576,COUNT(B$19:B$1048576)) | C5: =INDEX(C$19:C$1048576,COUNT(C$19:C$1048576)) | D5: =INDEX(D$19:D$1048576,COUNT(D$19:D$1048576)) | E5: =INDEX(E$19:E$1048576,COUNT(E$19:E$1048576)) | F5: =INDEX(F$19:F$1048576,COUNT(F$19:F$1048576)) | G5: =INDEX(G$19:G$1048576,COUNT(G$19:G$1048576)) | H5: =INDEX(H$19:H$1048576,COUNT(H$19:H$1048576)) | I5: =INDEX(I$19:I$1048576,COUNT(I$19:I$1048576)) | ... BM5: =INDEX(BM$19:BM$1048576,COUNT(BM$19:BM$1048576))
A6: Quarterly change | B6: =INDEX(B$19:B$1048576,COUNT(B$19:B$1048576))-INDEX(B$19:B$1048576,COUNT(B$19:B$1048576)-3) | C6: =INDEX(C$19:C$1048576,COUNT(C$19:C$1048576))-INDEX(C$19:C$1048576,COUNT(C$19:C$1048576)-3) | D6: =INDEX(D$19:D$1048576,COUNT(D$19:D$1048576))-INDEX(D$19:D$1048576,COUNT(D$19:D$1048576)-3) | E6: =INDEX(E$19:E$1048576,COUNT(E$19:E$1048576))-INDEX(E$19:E$1048576,COUNT(E$19:E$1048576)-3) | F6: =INDEX(F$19:F$1048576,COUNT(F$19:F$1048576))-INDEX(F$19:F$1048576,COUNT(F$19:F$1048576)-3) | G6: =INDEX(G$19:G$1048576,COUNT(G$19:G$1048576))-INDEX(G$19:G$1048576,COUNT(G$19:G$1048576)-3) | H6: =INDEX(H$19:H$1048576,COUNT(H$19:H$1048576))-INDEX(H$19:H$1048576,COUNT(H$19:H$1048576)-3) | I6: =INDEX(I$19:I$1048576,COUNT(I$19:I$1048576))-INDEX(I$19:I$1048576,COUNT(I$19:I$1048576)-3) | ... BM6: =INDEX(BM$19:BM$1048576,COUNT(BM$19:BM$1048576))-INDEX(BM$19:BM$1048576,COUNT(BM$19:BM$1048576)-3)
A7: Change year on year | B7: =INDEX(B$19:B$1048576,COUNT(B$19:B$1048576))-INDEX(B$19:B$1048576,COUNT(B$19:B$1048576)-12) | C7: =INDEX(C$19:C$1048576,COUNT(C$19:C$1048576))-INDEX(C$19:C$1048576,COUNT(C$19:C$1048576)-12) | D7: =INDEX(D$19:D$1048576,COUNT(D$19:D$1048576))-INDEX(D$19:D$1048576,COUNT(D$19:D$1048576)-12) | E7: =INDEX(E$19:E$1048576,COUNT(E$19:E$1048576))-INDEX(E$19:E$1048576,COUNT(E$19:E$1048576)-12) | F7: =INDEX(F$19:F$1048576,COUNT(F$19:F$1048576))-INDEX(F$19:F$1048576,COUNT(F$19:F$1048576)-12) | G7: =INDEX(G$19:G$1048576,COUNT(G$19:G$1048576))-INDEX(G$19:G$1048576,COUNT(G$19:G$1048576)-12) | H7: =INDEX(H$19:H$1048576,COUNT(H$19:H$1048576))-INDEX(H$19:H$1048576,COUNT(H$19:H$1048576)-12) | I7: =INDEX(I$19:I$1048576,COUNT(I$19:I$1048576))-INDEX(I$19:I$1048576,COUNT(I$19:I$1048576)-12) | ... BM7: =INDEX(BM$19:BM$1048576,COUNT(BM$19:BM$1048576))-INDEX(BM$19:BM$1048576,COUNT(BM$19:BM$1048576)-12)
A8: Change since Covid (Dec 19-Feb 20) | B8: =INDEX(B$19:B$1048576,COUNT(B$19:B$1048576))-B$352 | C8: =INDEX(C$19:C$1048576,COUNT(C$19:C$1048576))-C$352 | D8: =INDEX(D$19:D$1048576,COUNT(D$19:D$1048576))-D$352 | E8: =INDEX(E$19:E$1048576,COUNT(E$19:E$1048576))-E$352 | F8: =INDEX(F$19:F$1048576,COUNT(F$19:F$1048576))-F$352 | G8: =INDEX(G$19:G$1048576,COUNT(G$19:G$1048576))-G$352 | H8: =INDEX(H$19:H$1048576,COUNT(H$19:H$1048576))-H$352 | I8: =INDEX(I$19:I$1048576,COUNT(I$19:I$1048576))-I$352 | ... BM8: =INDEX(BM$19:BM$1048576,COUNT(BM$19:BM$1048576))-BM$352
A9: Change since 2010 election | B9: =INDEX(B$19:B$1048576,COUNT(B$19:B$1048576))-B$234 | C9: =INDEX(C$19:C$1048576,COUNT(C$19:C$1048576))-C$234 | D9: =INDEX(D$19:D$1048576,COUNT(D$19:D$1048576))-D$234 | E9: =INDEX(E$19:E$1048576,COUNT(E$19:E$1048576))-E$234 | F9: =INDEX(F$19:F$1048576,COUNT(F$19:F$1048576))-F$234 | G9: =INDEX(G$19:G$1048576,COUNT(G$19:G$1048576))-G$234 | H9: =INDEX(H$19:H$1048576,COUNT(H$19:H$1048576))-H$234 | I9: =INDEX(I$19:I$1048576,COUNT(I$19:I$1048576))-I$234 | ... BM9: =INDEX(BM$19:BM$1048576,COUNT(BM$19:BM$1048576))-BM$234
A10: Change since 2024 election | B10: =INDEX(B$19:B$1048576,COUNT(B$19:B$1048576))-B$404 | C10: =INDEX(C$19:C$1048576,COUNT(C$19:C$1048576))-C$404 | D10: =INDEX(D$19:D$1048576,COUNT(D$19:D$1048576))-D$404 | E10: =INDEX(E$19:E$1048576,COUNT(E$19:E$1048576))-E$404 | F10: =INDEX(F$19:F$1048576,COUNT(F$19:F$1048576))-F$404 | G10: =INDEX(G$19:G$1048576,COUNT(G$19:G$1048576))-G$404 | H10: =INDEX(H$19:H$1048576,COUNT(H$19:H$1048576))-H$404 | I10: =INDEX(I$19:I$1048576,COUNT(I$19:I$1048576))-I$404 | ... BM10: =INDEX(BM$19:BM$1048576,COUNT(BM$19:BM$1048576))-BM$404
A11: Date of publication: | B11: 46133 | G11: Date of next publication: | H11: 46161 | BM11: Source: Labour Force Survey
A12: Inquiries: Email: | B12: labour.market@ons.gov.uk | G12: Telephone: | H12: 01633 455400
A13: United Kingdom (thousands) seasonally adjusted
B14: Aged 16 and over | J14: Aged 16-64 | R14: Aged 16-17 | Z14: Aged 18-24 | AH14: Aged 25-34 | AP14: Aged 35-49 | AX14: Aged 50-64 | BF14: Age 65+
B15: Employment | D15: Unemployment | F15: Activity | H15: Inactivity | J15: Employment | L15: Unemployment | N15: Activity | P15: Inactivity | R15: Employment | T15: Unemployment | V15: Activity | X15: Inactivity | Z15: Employment | AB15: Unemployment | AD15: Activity | AF15: Inactivity | AH15: Employment | AJ15: Unemployment | AL15: Activity | AN15: Inactivity | AP15: Employment | AR15: Unemployment | AT15: Activity | AV15: Inactivity | AX15: Employment | AZ15: Unemployment | BB15: Activity | BD15: Inactivity | BF15: Employment | BH15: Unemployment | BJ15: Activity | BL15: Inactivity
B16: level | C16: rate (%) | D16: level | E16: rate (%) | F16: level | G16: rate (%) | H16: level | I16: rate (%) | J16: level | K16: rate (%) | L16: level | M16: rate (%) | N16: level | O16: rate (%) | P16: level | Q16: rate (%) | R16: level | S16: rate (%) | T16: level | U16: rate (%) | V16: level | W16: rate (%) | X16: level | Y16: rate (%) | Z16: level | AA16: rate (%) | AB16: level | AC16: rate (%) | AD16: level | AE16: rate (%) | AF16: level | AG16: rate (%) | AH16: level | AI16: rate (%) | AJ16: level | AK16: rate (%) | AL16: level | AM16: rate (%) | AN16: level | AO16: rate (%) | AP16: level | AQ16: rate (%) | AR16: level | AS16: rate (%) | AT16: level | AU16: rate (%) | AV16: level | AW16: rate (%) | AX16: level | AY16: rate (%) | AZ16: level | BA16: rate (%) | BB16: level | BC16: rate (%) | BD16: level | BE16: rate (%) | BF16: level | BG16: rate (%) | BH16: level | BI16: rate (%) | BJ16: level | BK16: rate (%) | BL16: level | BM16: rate (%)
A17: Dataset identifier code | B17: MGRZ | C17: MGSR | D17: MGSC | E17: MGSX | F17: MGSF | G17: MGWG | H17: MGSI | I17: YBTC | J17: LF2G | K17: LF24 | L17: LF2I | M17: LF2Q | N17: LF2K | O17: LF22 | P17: LF2M | Q17: LF2S | R17: YBTO | S17: YBUA | T17: YBVH | U17: YBVK | V17: YBZL | W17: YCAG | X17: YCAS | Y17: LWEX | Z17: YBTR | AA17: YBUD | AB17: YBVN | AC17: YBVQ | AD17: YBZO | AE17: YCAJ | AF17: YCAV | AG17: LWFA | AH17: YBTU | AI17: YBUG | AJ17: YCGM | AK17: YCGP | AL17: YBZR | AM17: YCAM | AN17: YCAY | AO17: LWFD | AP17: YBTX | AQ17: YBUJ | AR17: YCGS | AS17: YCGV | AT17: YBZU | AU17: YCAP | AV17: YCBB | AW17: LWFG | AX17: LF26 | AY17: LF2U | AZ17: LF28 | BA17: LF2E | BB17: LF3A | BC17: LF2C | BD17: LF2A | BE17: LF2W | BF17: LFK4 | BG17: LFK6 | BH17: K5HU | BI17: K5HW | BJ17: LFK8 | BK17: LFL2 | BL17: LFL4 | BM17: LFL6
A19: Mar-May 1992 | B19: 25635937 | C19: 56.978873 | D19: 2795738.4 | E19: 9.8331819 | F19: 28431675 | G19: 63.19273 | H19: 16560329 | I19: 36.80727 | J19: 25157591 | K19: 69.194504 | L19: 2771842.3 | M19: 9.9244488 | N19: 27929433 | O19: 76.818297 | P19: 8428354.6 | Q19: 23.181703 | R19: 672842.98 | S19: 48.815635 | T19: 148298.6 | U19: 18.060053 | V19: 821141.59 | W19: 59.574892 | X19: 557193.41 | Y19: 40.425108 | Z19: 3807969.1 | AA19: 65.851182 | AB19: 711645.67 | AC19: 15.745715 | AD19: 4519614.8 | AE19: 78.157666 | AF19: 1263074.2 | AG19: 21.842334 | AH19: 6569245 | AI19: 73.761625 | AJ19: 766486.76 | AK19: 10.448675 | AL19: 7335731.8 | AM19: 82.367988 | AN19: 1570315.2 | AO19: 17.632012 | AP19: 9130969.3 | AQ19: 79.563995 | AR19: 715160.37 | AS19: 7.2633653 | AT19: 9846129.7 | AU19: 85.795646 | AV19: 1630128.3 | AW19: 14.204354 | AX19: 4976564.7 | AY19: 56.459105 | AZ19: 430250.91 | BA19: 7.9575657 | BB19: 5406815.6 | BC19: 61.3403 | BD19: 3407643.4 | BE19: 38.6597 | BF19: 478345.94 | BG19: 5.5401202 | BH19: 23896.055 | BI19: 4.7578768 | BJ19: 502242 | BK19: 5.8168802 | BL19: 8131974 | BM19: 94.18312
A20: Apr-Jun 1992 | B20: 25605421 | C20: 56.906189 | D20: 2777367.7 | E20: 9.785394 | F20: 28382788 | G20: 63.078687 | H20: 16613057 | I20: 36.921313 | J20: 25121755 | K20: 69.095274 | L20: 2755380.3 | M20: 9.8840153 | N20: 27877135 | O20: 76.673716 | P20: 8481002.7 | Q20: 23.326284 | R20: 664951.75 | S20: 48.404968 | T20: 154422.9 | U20: 18.846433 | V20: 819374.64 | W20: 59.646137 | X20: 554351.61 | Y20: 40.353863 | Z20: 3773820.3 | AA20: 65.44936 | AB20: 703256.67 | AC20: 15.707942 | AD20: 4477077 | AE20: 77.64594 | AF20: 1288938.6 | AG20: 22.35406 | AH20: 6562285.8 | AI20: 73.607934 | AJ20: 774481.14 | AK20: 10.556164 | AL20: 7336767 | AM20: 82.295144 | AN20: 1578421.2 | AO20: 17.704856 | AP20: 9154912.9 | AQ20: 79.688748 | AR20: 691103.96 | AS20: 7.0191223 | AT20: 9846016.8 | AU20: 85.704448 | AV20: 1642321.4 | AW20: 14.295552 | AX20: 4965784.3 | AY20: 56.334176 | AZ20: 432115.65 | BA20: 8.0052549 | BB20: 5397900 | BC20: 61.236297 | BD20: 3416970 | BE20: 38.763703 | BF20: 483665.56 | BG20: 5.5994671 | BH20: 21987.331 | BI20: 4.3483051 | BJ20: 505652.89 | BK20: 5.8540177 | BL20: 8132054 | BM20: 94.145982
A21: May-Jul 1992 | B21: 25541631 | C21: 56.759881 | D21: 2802624.9 | E21: 9.8878055 | F21: 28344256 | G21: 62.988013 | H21: 16655188 | I21: 37.011987 | J21: 25071012 | K21: 68.95567 | L21: 2780378.7 | M21: 9.9829079 | N21: 27851391 | O21: 76.602863 | P21: 8506768.3 | Q21: 23.397137 | R21: 657021.66 | S21: 47.988417 | T21: 160526.33 | U21: 19.635096 | V21: 817547.99 | W21: 59.713152 | X21: 551577.51 | Y21: 40.286848 | Z21: 3732657.6 | AA21: 64.922411 | AB21: 704380.25 | AC21: 15.875011 | AD21: 4437037.9 | AE21: 77.173753 | AF21: 1312375.3 | AG21: 22.826247 | AH21: 6563532.7 | AI21: 73.546748 | AJ21: 774921.42 | AK21: 10.559737 | AL21: 7338454.1 | AM21: 82.230022 | AN21: 1585846.2 | AO21: 17.769978 | AP21: 9147971.3 | AQ21: 79.549054 | AR21: 702795.56 | AS21: 7.1344248 | AT21: 9850766.9 | AU21: 85.660434 | AV21: 1649019.5 | AW21: 14.339566 | AX21: 4969829 | AY21: 56.375814 | AZ21: 437755.16 | BA21: 8.0952074 | BB21: 5407584.2 | BC21: 61.341539 | BD21: 3407949.8 | BE21: 38.658461 | BF21: 470618.68 | BG21: 5.4461656 | BH21: 22246.196 | BI21: 4.51365 | BJ21: 492864.88 | BK21: 5.7036065 | BL21: 8148420 | BM21: 94.296394
A22: Jun-Aug 1992 | B22: 25525070 | C22: 56.721622 | D22: 2816125.8 | E22: 9.9365103 | F22: 28341196 | G22: 62.979596 | H22: 16659404 | I22: 37.020404 | J22: 25060700 | K22: 68.931149 | L22: 2794467.3 | M22: 10.032132 | N22: 27855168 | O22: 76.61752 | P22: 8500965.7 | Q22: 23.38248 | R22: 655096.25 | S22: 48.013865 | T22: 155254.86 | U22: 19.158962 | V22: 810351.11 | W22: 59.392934 | X22: 554038.64 | Y22: 40.607066 | Z22: 3719998.3 | AA22: 64.885011 | AB22: 714329.99 | AC22: 16.109091 | AD22: 4434328.3 | AE22: 77.344508 | AF22: 1298888.4 | AG22: 22.655492 | AH22: 6566665.2 | AI22: 73.542227 | AJ22: 775662.24 | AK22: 10.564256 | AL22: 7342327.5 | AM22: 82.229121 | AN22: 1586781 | AO22: 17.770879 | AP22: 9143812.7 | AQ22: 79.452506 | AR22: 703958.08 | AS22: 7.1484003 | AT22: 9847770.8 | AU22: 85.569345 | AV22: 1660755.7 | AW22: 14.430655 | AX22: 4975128 | AY22: 56.401643 | AZ22: 445262.13 | BA22: 8.2145771 | BB22: 5420390.1 | BC22: 61.449456 | BD22: 3400501.9 | BE22: 38.550544 | BF22: 464369.35 | BG22: 5.3718688 | BH22: 21658.542 | BI22: 4.4562342 | BJ22: 486027.9 | BK22: 5.6224168 | BL22: 8158437.9 | BM22: 94.377583
A23: Jul-Sep 1992 | B23: 25509005 | C23: 56.682283 | D23: 2814524.8 | E23: 9.9370554 | F23: 28323530 | G23: 62.936297 | H23: 16679960 | I23: 37.063703 | J23: 25051022 | K23: 68.904267 | L23: 2793342.4 | M23: 10.031985 | N23: 27844364 | O23: 76.587515 | P23: 8511906.3 | Q23: 23.412485 | R23: 648817.45 | S23: 47.720183 | T23: 146301.37 | U23: 18.399938 | V23: 795118.82 | W23: 58.480572 | X23: 564510.18 | Y23: 41.519428 | Z23: 3700258.4 | AA23: 64.724227 | AB23: 723869.61 | AC23: 16.36186 | AD23: 4424128 | AE23: 77.386019 | AF23: 1292832.3 | AG23: 22.613981 | AH23: 6586437.2 | AI23: 73.720371 | AJ23: 762085.43 | AK23: 10.370594 | AL23: 7348522.7 | AM23: 82.250206 | AN23: 1585829 | AO23: 17.749794 | AP23: 9154876.5 | AQ23: 79.480524 | AR23: 712240.98 | AS23: 7.2183288 | AT23: 9867117.4 | AU23: 85.664036 | AV23: 1651272.2 | AW23: 14.335964 | AX23: 4960632.4 | AY23: 56.198778 | AZ23: 448845.05 | BA23: 8.2973827 | BB23: 5409477.5 | BC23: 61.283723 | BD23: 3417462.5 | BE23: 38.716277 | BF23: 457983.03 | BG23: 5.2963045 | BH23: 21182.41 | BI23: 4.4206882 | BJ23: 479165.44 | BK23: 5.5412666 | BL23: 8168053.2 | BM23: 94.458733
A24: Aug-Oct 1992 | B24: 25454432 | C24: 56.55781 | D24: 2849869.1 | E24: 10.068678 | F24: 28304301 | G24: 62.890002 | H24: 16701741 | I24: 37.109998 | J24: 24999843 | K24: 68.764542 | L24: 2829973 | M24: 10.168853 | N24: 27829816 | O24: 76.548662 | P24: 8525902.4 | Q24: 23.451338 | R24: 628524.21 | S24: 46.391089 | T24: 135175.21 | U24: 17.700054 | V24: 763699.42 | W24: 56.36831 | X24: 591138.83 | Y24: 43.63169 | Z24: 3693704.8 | AA24: 64.794223 | AB24: 740436.82 | AC24: 16.698538 | AD24: 4434141.6 | AE24: 77.782816 | AF24: 1266528.3 | AG24: 22.217184 | AH24: 6575853.7 | AI24: 73.560218 | AJ24: 775080.19 | AK24: 10.543969 | AL24: 7350933.9 | AM24: 82.230585 | AN24: 1588481.9 | AO24: 17.769415 | AP24: 9157510.7 | AQ24: 79.437958 | AR24: 727787.21 | AS24: 7.3623194 | AT24: 9885297.9 | AU24: 85.751238 | AV24: 1642579.9 | AW24: 14.248762 | AX24: 4944250 | AY24: 55.97528 | AZ24: 451493.6 | BA24: 8.3675882 | BB24: 5395743.6 | BC24: 61.086769 | BD24: 3437173.4 | BE24: 38.913231 | BF24: 454588.67 | BG24: 5.2551638 | BH24: 19896.06 | BI24: 4.1931929 | BJ24: 474484.73 | BK24: 5.4851674 | BL24: 8175838.9 | BM24: 94.514833
A25: Sep-Nov 1992 | B25: 25406419 | C25: 56.449606 | D25: 2898811.3 | E25: 10.241257 | F25: 28305230 | G25: 62.890371 | H25: 16702026 | I25: 37.109629 | J25: 24962923 | K25: 68.666128 | L25: 2880096.3 | M25: 10.344052 | N25: 27843020 | O25: 76.58848 | P25: 8511037.4 | Q25: 23.41152 | R25: 623263.78 | S25: 46.162438 | T25: 136924.83 | U25: 18.011955 | V25: 760188.61 | W25: 56.303865 | X25: 589964.89 | Y25: 43.696135 | Z25: 3682050 | AA25: 64.774538 | AB25: 750677.65 | AC25: 16.934892 | AD25: 4432727.6 | AE25: 77.980442 | AF25: 1251681.9 | AG25: 22.019558 | AH25: 6571774.9 | AI25: 73.47512 | AJ25: 787965.68 | AK25: 10.706433 | AL25: 7359740.6 | AM25: 82.284897 | AN25: 1584477.4 | AO25: 17.715103 | AP25: 9161864.5 | AQ25: 79.415391 | AR25: 730505.38 | AS25: 7.3845336 | AT25: 9892369.9 | AU25: 85.747439 | AV25: 1644266.1 | AW25: 14.252561 | AX25: 4923970.1 | AY25: 55.70959 | AZ25: 474022.79 | BA25: 8.7814639 | BB25: 5397992.9 | BC25: 61.072664 | BD25: 3440647.1 | BE25: 38.927336 | BF25: 443495.8 | BG25: 5.1252233 | BH25: 18714.996 | BI25: 4.0490174 | BJ25: 462210.8 | BK25: 5.3415017 | BL25: 8190988.7 | BM25: 94.658498
A26: Oct-Dec 1992 | B26: 25335708 | C26: 56.289377 | D26: 2931640.3 | E26: 10.371119 | F26: 28267348 | G26: 62.802722 | H26: 16742402 | I26: 37.197278 | J26: 24904858 | K26: 68.507651 | L26: 2912254.2 | M26: 10.46929 | N26: 27817112 | O26: 76.518606 | P26: 8536284.2 | Q26: 23.481394 | R26: 613179.3 | S26: 45.576197 | T26: 143304.85 | U26: 18.943537 | V26: 756484.15 | W26: 56.227714 | X26: 588909.6 | Y26: 43.772286 | Z26: 3657106.4 | AA26: 64.520168 | AB26: 749834.88 | AC26: 17.01486 | AD26: 4406941.3 | AE26: 77.749062 | AF26: 1261218.8 | AG26: 22.250938 | AH26: 6566330.4 | AI26: 73.371467 | AJ26: 796807.58 | AK26: 10.821576 | AL26: 7363138 | AM26: 82.274909 | AN26: 1586295.1 | AO26: 17.725091 | AP26: 9151189.4 | AQ26: 79.257564 | AR26: 741700.09 | AS26: 7.4973049 | AT26: 9892889.5 | AU26: 85.681356 | AV26: 1653250.7 | AW26: 14.318644 | AX26: 4917052.2 | AY26: 55.595914 | AZ26: 480606.78 | BA26: 8.9039856 | BB26: 5397659 | BC26: 61.030018 | BD26: 3446610 | BE26: 38.969982 | BF26: 430849.95 | BG26: 4.9772685 | BH26: 19386.125 | BI26: 4.3057689 | BJ26: 450236.08 | BK26: 5.2012211 | BL26: 8206117.3 | BM26: 94.798779
A27: Nov-Jan 1993 | B27: 25301164 | C27: 56.210098 | D27: 2982756.3 | E27: 10.545767 | F27: 28283920 | G27: 62.836711 | H27: 16727857 | I27: 37.163289 | J27: 24869383 | K27: 68.411497 | L27: 2964559.6 | M27: 10.650879 | N27: 27833942 | O27: 76.566503 | P27: 8518694 | Q27: 23.433497 | R27: 601737.22 | S27: 44.888946 | T27: 148625.82 | U27: 19.807188 | V27: 750363.04 | W27: 55.976271 | X27: 590138.96 | Y27: 44.023729 | Z27: 3642900.1 | AA27: 64.453285 | AB27: 758732.77 | AC27: 17.23753 | AD27: 4401632.8 | AE27: 77.87743 | AF27: 1250367.8 | AG27: 22.12257 | AH27: 6577421.7 | AI27: 73.455902 | AJ27: 802411.97 | AK27: 10.873036 | AL27: 7379833.7 | AM27: 82.417149 | AN27: 1574411.7 | AO27: 17.582851 | AP27: 9134290.6 | AQ27: 79.048594 | AR27: 755263.86 | AS27: 7.6369857 | AT27: 9889554.5 | AU27: 85.584684 | AV27: 1665730.9 | AW27: 14.415316 | AX27: 4913033.1 | AY27: 55.510717 | AZ27: 499525.19 | BA27: 9.2290034 | BB27: 5412558.3 | BC27: 61.154684 | BD27: 3438044.7 | BE27: 38.845316 | BF27: 431780.84 | BG27: 4.986417 | BH27: 18196.685 | BI27: 4.0439097 | BJ27: 449977.53 | BK27: 5.1965612 | BL27: 8209162.8 | BM27: 94.803439
A28: Dec-Feb 1993 | B28: 25274286 | C28: 56.147416 | D28: 3023283.2 | E28: 10.683897 | F28: 28297569 | G28: 62.86371 | H28: 16716588 | I28: 37.13629 | J28: 24839004 | K28: 68.329654 | L28: 3005600.8 | M28: 10.794194 | N28: 27844605 | O28: 76.597766 | P28: 8507114.4 | Q28: 23.402234 | R28: 589709.19 | S28: 44.1438 | T28: 147847.45 | U28: 20.045572 | V28: 737556.64 | W28: 55.211201 | X28: 598325.61 | Y28: 44.788799 | Z28: 3626688.4 | AA28: 64.350812 | AB28: 774878.08 | AC28: 17.604598 | AD28: 4401566.4 | AE28: 78.100004 | AF28: 1234241.8 | AG28: 21.899996 | AH28: 6573950.2 | AI28: 73.372982 | AJ28: 815460.81 | AK28: 11.035532 | AL28: 7389411.1 | AM28: 82.474479 | AN28: 1570222.4 | AO28: 17.525521 | AP28: 9123860.8 | AQ28: 78.895396 | AR28: 770251.41 | AS28: 7.7849472 | AT28: 9894112.2 | AU28: 85.555876 | AV28: 1670391.3 | AW28: 14.444124 | AX28: 4924795.6 | AY28: 55.610385 | AZ28: 497163.07 | BA28: 9.1694367 | BB28: 5421958.7 | BC28: 61.224309 | BD28: 3433933.3 | BE28: 38.775691 | BF28: 435281.59 | BG28: 5.0249321 | BH28: 17682.355 | BI28: 3.9037004 | BJ28: 452963.95 | BK28: 5.2290589 | BL28: 8209473.3 | BM28: 94.770941
A29: Jan-Mar 1993 | B29: 25282289 | C29: 56.163389 | D29: 3003526.8 | E29: 10.618491 | F29: 28285816 | G29: 62.835579 | H29: 16729789 | I29: 37.164421 | J29: 24847113 | K29: 68.354168 | L29: 2984739.8 | M29: 10.724187 | N29: 27831853 | O29: 76.565158 | P29: 8518692.9 | Q29: 23.434842 | R29: 587790.99 | S29: 44.156249 | T29: 143512.75 | U29: 19.624233 | V29: 731303.73 | W29: 54.937266 | X29: 599857.77 | Y29: 45.062734 | Z29: 3602671.5 | AA29: 64.109929 | AB29: 780912.52 | AC29: 17.814476 | AD29: 4383584 | AE29: 78.006352 | AF29: 1235937.9 | AG29: 21.993648 | AH29: 6591842.4 | AI29: 73.534333 | AJ29: 802247.85 | AK29: 10.849852 | AL29: 7394090.2 | AM29: 82.483692 | AN29: 1570215.4 | AO29: 17.516308 | AP29: 9128037.7 | AQ29: 78.867686 | AR29: 765601.85 | AS29: 7.7383237 | AT29: 9893639.6 | AU29: 85.482607 | AV29: 1680223.1 | AW29: 14.517393 | AX29: 4936770.4 | AY29: 55.709105 | AZ29: 492464.82 | BA29: 9.0706112 | BB29: 5429235.2 | BC29: 61.266336 | BD29: 3432458.8 | BE29: 38.733664 | BF29: 435176.21 | BG29: 5.0221955 | BH29: 18787.035 | BI29: 4.1384485 | BJ29: 453963.25 | BK29: 5.2390092 | BL29: 8211095.9 | BM29: 94.760991
A30: Feb-Apr 1993 | B30: 25258217 | C30: 56.10629 | D30: 2988474.6 | E30: 10.57991 | F30: 28246692 | G30: 62.744614 | H30: 16771821 | I30: 37.255386 | J30: 24824126 | K30: 68.291867 | L30: 2969360.9 | M30: 10.683657 | N30: 27793487 | O30: 76.460663 | P30: 8556560.4 | Q30: 23.539337 | R30: 576754.25 | S30: 43.483966 | T30: 140457.66 | U30: 19.583843 | V30: 717211.91 | W30: 54.073668 | X30: 609148.84 | Y30: 45.926332 | Z30: 3566918.9 | AA30: 63.657292 | AB30: 773854.39 | AC30: 17.82757 | AD30: 4340773.2 | AE30: 77.467944 | AF30: 1262542.2 | AG30: 22.532056 | AH30: 6606869.8 | AI30: 73.659732 | AJ30: 795947.06 | AK30: 10.751949 | AL30: 7402816.9 | AM30: 82.533715 | AN30: 1566629 | AO30: 17.466285 | AP30: 9125446.4 | AQ30: 78.780012 | AR30: 765785.88 | AS30: 7.7420675 | AT30: 9891232.3 | AU30: 85.391045 | AV30: 1692221.6 | AW30: 14.608955 | AX30: 4948137.2 | AY30: 55.80099 | AZ30: 493315.96 | BA30: 9.0658864 | BB30: 5441453.1 | BC30: 61.364199 | BD30: 3426018.9 | BE30: 38.635801 | BF30: 434090.92 | BG30: 5.0077023 | BH30: 19113.649 | BI30: 4.2174439 | BJ30: 453204.57 | BK30: 5.2281986 | BL30: 8215260.5 | BM30: 94.771801
... A424: Dec-Feb 2026 | B424: 34327521 | C424: 60.677477 | D424: 1780058.1 | E424: 4.9298737 | F424: 36107579 | G424: 63.823916 | H424: 20466166 | I424: 36.176084 | J424: 32610347 | K424: 75.040638 | L424: 1730892.8 | M424: 5.0402747 | N424: 34341240 | O424: 79.023647 | P424: 9115676.1 | Q424: 20.976353 | R424: 329590.74 | S424: 20.178164 | T424: 133181 | U424: 28.778984 | V424: 462771.74 | W424: 28.331755 | X424: 1170631.3 | Y424: 71.668245 | Z424: 3461915.3 | AA424: 59.002344 | AB424: 579658.15 | AC424: 14.342388 | AD424: 4041573.5 | AE424: 68.881612 | AF424: 1825846.5 | AG424: 31.118388 | AH424: 7697909.3 | AI424: 84.058537 | AJ424: 381019.59 | AK424: 4.7162142 | AL424: 8078928.9 | AM424: 88.21914 | AN424: 1078867.1 | AO424: 11.78086 | AP424: 11617757 | AQ424: 85.489756 | AR424: 354066.09 | AS424: 2.9574952 | AT424: 11971823 | AU424: 88.095167 | AV424: 1617824.9 | AW424: 11.904833 | AX424: 9503174.7 | AY424: 71.946606 | AZ424: 282967.99 | BA424: 2.8915171 | BB424: 9786142.7 | BC424: 74.0889 | BD424: 3422506.3 | BE424: 25.9111 | BF424: 1717174.1 | BG424: 13.091381 | BH424: 49165.241 | BI424: 2.7834539 | BJ424: 1766339.4 | BK424: 13.466207 | BL424: 11350490 | BM424: 86.533793

Sheet 3
B2: 46133 | F2: Date of next publication: | G2: 46161 | Z2: Source: Labour Force Survey
B3: labour.market@ons.gov.uk | F3: Telephone: | G3: 01633 455400
B5: All in employment | G5: Full-time and part-time workers1 | N5: Temporary employees (reasons for temporary working) | U5: Part-time workers (reasons for working part-time)3
B6: Total6 | C6: Employees | D6: Self employed | E6: Unpaid family workers | F6: Government supported training & employment programmes2 | G6: Total people working full-time | H6: Total people working part-time | I6: Employees working full-time | J6: Employees working part-time | K6: Self-employed people working full-time | L6: Self-employed people working part-time | M6: Total workers with second jobs | N6: Total | O6: Total as % of all employees | P6: Could not find permanent job | Q6: % that could not find permanent job | R6: Did not want permanent job | S6: Had a contract with period of training | T6: Some other reason | U6: Total4 | V6: Could not find full-time job | W6: % that could not find full-time job | X6: Did not want full-time job | Y6: Ill or disabled | Z6: Student or at school
C8: MGRN | D8: MGRQ | E8: MGRT | F8: MGRW | G8: YCBE | H8: YCBH | I8: YCBK | J8: YCBN | K8: YCBQ | L8: YCBT | M8: YCBW | N8: YCBZ | O8: YCCC | P8: YCCF | Q8: YCCI | R8: YCCL | S8: YCCO | T8: YCCR | U8: YCCU | V8: YCCX | W8: YCDA | X8: YCDD | Y8: YCDG | Z8: YCDJ
A9: 33664 | B9: 25635937 | C9: 21633538 | D9: 3451242.8 | E9: 179170.01 | F9: 371986.33 | G9: 19631892 | H9: 6004045.1 | I9: 16546500 | J9: 5087038 | K9: 2853526.8 | L9: 597715.99 | M9: 965983.98 | N9: 1287679.2 | O9: 5.9522356 | P9: 461932.96 | Q9: 35.873297 | R9: 363227.71 | S9: 69600.618 | T9: 392917.87 | U9: 5684753.9 | V9: 639834.7 | W9: 11.255275 | X9: 4335547.5 | Y9: 89703.748 | Z9: 611100.86
A10: 33695 | B10: 25605421 | C10: 21575567 | D10: 3486917.3 | E10: 175107.3 | F10: 367829.04 | G10: 19582667 | H10: 6022753.8 | I10: 16473112 | J10: 5102454.6 | K10: 2874530.1 | L10: 612387.21 | M10: 952951.43 | N10: 1272014.8 | O10: 5.8956261 | P10: 464073.13 | Q10: 36.483313 | R10: 358429.71 | S10: 73443.437 | T10: 376068.49 | U10: 5714841.8 | V10: 663229.06 | W10: 11.605379 | X10: 4340566.2 | Y10: 87725.093 | Z10: 615279.48
A11: 33725 | B11: 25541631 | C11: 21535114 | D11: 3469236 | E11: 171911.34 | F11: 365369.87 | G11: 19528878 | H11: 6012753.4 | I11: 16437125 | J11: 5097988.8 | K11: 2860737.2 | L11: 608498.79 | M11: 938332.76 | N11: 1275347.1 | O11: 5.9221748 | P11: 476947.51 | Q11: 37.397468 | R11: 355203.49 | S11: 74363.527 | T11: 368832.56 | U11: 5706487.6 | V11: 673285.62 | W11: 11.7986 | X11: 4332174.1 | Y11: 85862.188 | Z11: 609504.2
A12: 33756 | B12: 25525070 | C12: 21536104 | D12: 3444530.9 | E12: 176280.8 | F12: 368153.94 | G12: 19519740 | H12: 6005329.8 | I12: 16447790 | J12: 5088314.4 | K12: 2837419.5 | L12: 607111.42 | M12: 926793.6 | N12: 1275264.8 | O12: 5.9215203 | P12: 499301.85 | Q12: 39.152799 | R12: 333783.79 | S12: 79535.898 | T12: 362643.24 | U12: 5695425.8 | V12: 691888.97 | W12: 12.148152 | X12: 4304323.8 | Y12: 83204.765 | Z12: 613616.66
A13: 33786 | B13: 25509005 | C13: 21551256 | D13: 3410669 | E13: 177758.76 | F13: 369320.9 | G13: 19492207 | H13: 6016797.6 | I13: 16448423 | J13: 5102833 | K13: 2811239.1 | L13: 599429.83 | M13: 941046.36 | N13: 1276410 | O13: 5.922671 | P13: 506584.88 | Q13: 39.688257 | R13: 323042.53 | S13: 71573.416 | T13: 375209.18 | U13: 5702262.8 | V13: 709357.14 | W13: 12.439924 | X13: 4295323.5 | Y13: 84175.957 | Z13: 609386.62
A14: 33817 | B14: 25454432 | C14: 21504645 | D14: 3409118.5 | E14: 177080.08 | F14: 363588.45 | G14: 19437329 | H14: 6017102.9 | I14: 16402691 | J14: 5101954.4 | K14: 2810315.3 | L14: 598803.24 | M14: 953288.87 | N14: 1295321.6 | O14: 6.0234501 | P14: 518295.77 | Q14: 40.012904 | R14: 328460.54 | S14: 78464.346 | T14: 370100.9 | U14: 5700757.6 | V14: 723396.54 | W14: 12.689481 | X14: 4288609.7 | Y14: 77597.304 | Z14: 604078.36
A15: 33848 | B15: 25406419 | C15: 21477798 | D15: 3390686.3 | E15: 176689.82 | F15: 361244.92 | G15: 19388788 | H15: 6017631 | I15: 16393064 | J15: 5084734.4 | K15: 2777089.5 | L15: 613596.79 | M15: 967956.37 | N15: 1300565.2 | O15: 6.0553937 | P15: 505981.47 | Q15: 38.904736 | R15: 349565.8 | S15: 76473.095 | T15: 368544.85 | U15: 5698331.2 | V15: 725488.62 | W15: 12.731598 | X15: 4281842.8 | Y15: 84037.366 | Z15: 597733.92
A16: 33878 | B16: 25335708 | C16: 21428737 | D16: 3386359.1 | E16: 171112.81 | F16: 349498.44 | G16: 19327810 | H16: 6007897.4 | I16: 16348948 | J16: 5079788.9 | K16: 2766108.9 | L16: 620250.19 | M16: 955365.02 | N16: 1321775 | O16: 6.1682356 | P16: 514478.57 | Q16: 38.923309 | R16: 362079.64 | S16: 78258.475 | T16: 366958.33 | U16: 5700039.1 | V16: 731598.34 | W16: 12.83497 | X16: 4279209.5 | Y16: 87856.901 | Z16: 589836.26
A17: 34274 | B17: 25301164 | C17: 21415689 | D17: 3368357 | E17: 169027.57 | F17: 348089.98 | G17: 19306261 | H17: 5994902.2 | I17: 16350439 | J17: 5065250 | K17: 2745020.2 | L17: 623336.8 | M17: 972244.78 | N17: 1335289.1 | O17: 6.2350975 | P17: 531015.74 | Q17: 39.767849 | R17: 362451.4 | S17: 77391.897 | T17: 364430.05 | U17: 5688586.8 | V17: 742775.52 | W17: 13.057294 | X17: 4257412.1 | Y17: 89384.295 | Z17: 589312.26
A18: 34304 | B18: 25274286 | C18: 21376365 | D18: 3387510.6 | E18: 163914.17 | F18: 346496.3 | G18: 19261829 | H18: 6012456.7 | I18: 16291051 | J18: 5085313.5 | K18: 2759105.1 | L18: 628405.52 | M18: 984483.35 | N18: 1326934.8 | O18: 6.2074858 | P18: 529218.56 | Q18: 39.882785 | R18: 365559.11 | S18: 81553.676 | T18: 350603.46 | U18: 5713719.1 | V18: 767413.71 | W18: 13.431072 | X18: 4264861.2 | Y18: 89766.984 | Z18: 582332.73
A19: 33970 | B19: 25282289 | C19: 21387671 | D19: 3380078 | E19: 160534.34 | F19: 354006.25 | G19: 19238566 | H19: 6043723.4 | I19: 16280197 | J19: 5107473.9 | K19: 2741829.3 | L19: 638248.63 | M19: 1011759.3 | N19: 1338002.6 | O19: 6.2559528 | P19: 540831.42 | Q19: 40.420806 | R19: 371221.19 | S19: 82825.136 | T19: 343124.84 | U19: 5745722.6 | V19: 782406.53 | W19: 13.6172 | X19: 4284135.2 | Y19: 88974.814 | Z19: 585758.61
A20: 34001 | B20: 25258217 | C20: 21347590 | D20: 3397157.4 | E20: 159133.48 | F20: 354336.13 | G20: 19205207 | H20: 6053010.1 | I20: 16247437 | J20: 5100153.4 | K20: 2747374.5 | L20: 649782.82 | M20: 1013711.3 | N20: 1327414.9 | O20: 6.218102 | P20: 536317.93 | Q20: 40.403186 | R20: 364469.78 | S20: 80180.855 | T20: 346446.38 | U20: 5749936.2 | V20: 786566.89 | W20: 13.679576 | X20: 4287090.6 | Y20: 87830.275 | Z20: 583403.66
... A330: 43800 | B330: 32720869 | C330: 27710952 | D330: 4832645.8 | E330: 133817.25 | F330: 43453.714 | G330: 24145875 | H330: 8574994 | I330: 20683648 | J330: 7027304.1 | K330: 3414157.3 | L330: 1418488.4 | M330: 1129355 | N330: 1545253.1 | O330: 5.5763262 | P330: 408201.13 | Q330: 26.416458 | R330: 453041.97 | S330: 135942.67 | T330: 548067.32 | U330: 8445792.5 | V330: 949525.98 | W330: 11.242592 | X330: 6094479.2 | Y330: 262197.63 | Z330: 1069480.6
B331: 32775975 | C331: 27695401 | D331: 4908912.2 | E331: 130071.29 | F331: 41590.66 | G331: 24155940 | H331: 8620035 | I331: 20633251 | J331: 7062150.2 | K331: 3476926.2 | L331: 1431986 | M331: 1092445.4 | N331: 1512987.5 | O331: 5.4629559 | P331: 370216.76 | Q331: 24.469254 | R331: 443228.76 | S331: 133266.25 | T331: 566275.75 | U331: 8494136.2 | V331: 911409.36 | W331: 10.729865 | X331: 6131628.3 | Y331: 268533.72 | Z331: 1114707.8
A332: 43497 | B332: 32843376 | C332: 27768203 | D332: 4903607.7 | E332: 132540.3 | F332: 39025.206 | G332: 24203750 | H332: 8639626.4 | I332: 20695754 | J332: 7072448.9 | K332: 3463321.5 | L332: 1440286.2 | M332: 1114540.8 | N332: 1471871.1 | O332: 5.3005631 | P332: 362637.89 | Q332: 24.637883 | R332: 433605.68 | S332: 135515.62 | T332: 540111.94 | U332: 8512735.1 | V332: 923738.9 | W332: 10.851259 | X332: 6152364.5 | Y332: 274479.55 | Z332: 1094998
A333: 43525 | B333: 32882262 | C333: 27760013 | D333: 4946329 | E333: 131253.43 | F333: 44666.624 | G333: 24134356 | H333: 8747905.7 | I333: 20666331 | J333: 7093681.5 | K333: 3419418 | L333: 1526911 | M333: 1147676.6 | N333: 1470827.7 | O333: 5.2983683 | P333: 356893.53 | Q333: 24.264808 | R333: 452854.16 | S333: 132006.98 | T333: 529073.07 | U333: 8620592.5 | V333: 923540.58 | W333: 10.713191 | X333: 6248998.8 | Y333: 277720.49 | Z333: 1104218.9
A334: 43556 | B334: 32963051 | C334: 27809356 | D334: 4969071.3 | E334: 134094.87 | F334: 50529.629 | G334: 24180489 | H334: 8782562.7 | I334: 20677423 | J334: 7131932.6 | K334: 3449731.3 | L334: 1519340 | M334: 1153414.5 | N334: 1474134.4 | O334: 5.3008577 | P334: 354687.82 | Q334: 24.060752 | R334: 448513.77 | S334: 132852.26 | T334: 538080.53 | U334: 8651272.7 | V334: 925247.82 | W334: 10.694933 | X334: 6261192 | Y334: 275836.77 | Z334: 1124057.4
A335: 43586 | B335: 32905931 | C335: 27792695 | D335: 4934877.2 | E335: 124109.51 | F335: 54248.954 | G335: 24232239 | H335: 8673691.5 | I335: 20715895 | J335: 7076800.2 | K335: 3462070.8 | L335: 1472806.4 | M335: 1160322.2 | N335: 1442873.1 | O335: 5.191555 | P335: 358788.31 | Q335: 24.866242 | R335: 417258.65 | S335: 123834.69 | T335: 542991.42 | U335: 8549606.6 | V335: 906047.52 | W335: 10.597535 | X335: 6182490.8 | Y335: 276814.57 | Z335: 1122029.6
A336: 43617 | B336: 32874593 | C336: 27738840 | D336: 4947071.4 | E336: 130583.26 | F336: 58097.679 | G336: 24253004 | H336: 8621588.3 | I336: 20690530 | J336: 7048310.1 | K336: 3508739.1 | L336: 1438332.3 | M336: 1157337 | N336: 1416641.4 | O336: 5.1070677 | P336: 342700.88 | Q336: 24.191083 | R336: 379159.75 | S336: 134722.68 | T336: 560058.05 | U336: 8486642.4 | V336: 886448.07 | W336: 10.445215 | X336: 6166577.2 | Y336: 278477.69 | Z336: 1095951.2
A337: 43647 | B337: 32896236 | C337: 27764104 | D337: 4951206.9 | E337: 121269.43 | F337: 59656.04 | G337: 24270305 | H337: 8625930.9 | I337: 20723679 | J337: 7040424.9 | K337: 3491743.3 | L337: 1459463.6 | M337: 1151615 | N337: 1439444.9 | O337: 5.1845539 | P337: 360126.04 | Q337: 25.018397 | R337: 381665.19 | S337: 132287.06 | T337: 565366.63 | U337: 8499888.5 | V337: 879936.73 | W337: 10.352333 | X337: 6172690.6 | Y337: 279613.2 | Z337: 1109205.2
A338: 43678 | B338: 32906942 | C338: 27763257 | D338: 4963628.3 | E338: 123181.58 | F338: 56875.171 | G338: 24275645 | H338: 8631297.2 | I338: 20749353 | J338: 7013904.1 | K338: 3479207.8 | L338: 1484420.5 | M338: 1152878.5 | N338: 1434112.4 | O338: 5.1655048 | P338: 368728.95 | Q338: 25.711301 | R338: 379795.93 | S338: 128529.29 | T338: 557058.2 | U338: 8498324.6 | V338: 879931.6 | W338: 10.354177 | X338: 6179787.5 | Y338: 281905.44 | Z338: 1099093.5
A339: 43709 | B339: 33005331 | C339: 27821697 | D339: 4993006.3 | E339: 134723.72 | F339: 55904.044 | G339: 24390156 | H339: 8615175 | I339: 20804098 | J339: 7017598.5 | K339: 3534573.2 | L339: 1458433.1 | M339: 1136900 | N339: 1465692.7 | O339: 5.2681645 | P339: 377418.67 | Q339: 25.750191 | R339: 397234.15 | S339: 117986.46 | T339: 573053.46 | U339: 8476031.6 | V339: 903887.61 | W339: 10.664042 | X339: 6132703.3 | Y339: 286740.04 | Z339: 1101044.2
A340: 43739 | B340: 33056798 | C340: 27857025 | D340: 5016560.6 | E340: 126831.94 | F340: 56381.009 | G340: 24445955 | H340: 8610843.8 | I340: 20834659 | J340: 7022365.8 | K340: 3557606.3 | L340: 1458954.3 | M340: 1177107.5 | N340: 1416432.2 | O340: 5.0846499 | P340: 369042.79 | Q340: 26.054391 | R340: 393910.85 | S340: 108656.5 | T340: 544822.05 | U340: 8481320.1 | V340: 918834.07 | W340: 10.833621 | X340: 6120211.3 | Y340: 296597.45 | Z340: 1094470.6
A341: 44136 | B341: 33102826 | C341: 27901418 | D341: 5011715.4 | E341: 131666.95 | F341: 58025.752 | G341: 24501294 | H341: 8601532.2 | I341: 20913911 | J341: 6987507.3 | K341: 3532183 | L341: 1479532.4 | M341: 1182477.2 | N341: 1460315.8 | O341: 5.2338407 | P341: 368150.45 | Q341: 25.210332 | R341: 416728.22 | S341: 122857.46 | T341: 552579.64 | U341: 8467039.8 | V341: 903962.84 | W341: 10.676256 | X341: 6101956.4 | Y341: 305672.19 | Z341: 1105945.3
A342: 44166 | B342: 33181308 | C342: 27973824 | D342: 5023296.7 | E342: 124368.7 | F342: 59818.186 | G342: 24477375 | H342: 8703932.5 | I342: 20900366 | J342: 7073457.9 | K342: 3522523.2 | L342: 1500773.6 | M342: 1211931.8 | N342: 1480006.3 | O342: 5.2906827 | P342: 385339 | Q342: 26.036308 | R342: 421754.64 | S342: 116942.95 | T342: 555969.69 | U342: 8574231.4 | V342: 873042.36 | W342: 10.182165 | X342: 6186700.5 | Y342: 307529.89 | Z342: 1162522.1
A343: 43831 | B343: 32976043 | C343: 27883208 | D343: 4918110.8 | E343: 116687.78 | F343: 58036.48 | G343: 24267359 | H343: 8708684.5 | I343: 20786317 | J343: 7096891 | K343: 3428085 | L343: 1490025.8 | M343: 1201604 | N343: 1512999.5 | O343: 5.4262032 | P343: 406207.15 | Q343: 26.847804 | R343: 425842.74 | S343: 117215.03 | T343: 563734.61 | U343: 8586916.8 | V343: 895468.38 | W343: 10.428288 | X343: 6203652.8 | Y343: 302601.09 | Z343: 1136811.5
... A414: 46357 | B414: 34327521 | C414: 29660985 | D414: 4474904.1 | E414: 126385.93 | F414: 65246.531 | G414: 25584391 | H414: 8743129.9 | I414: 22591893 | J414: 7069092 | K414: 2933438.9 | L414: 1541465.2 | M414: 1272895.8 | N414: 1636864.3 | O414: 5.5185772 | P414: 381201.22 | Q414: 23.288504 | R414: 431377.07 | S414: 169303.54 | T414: 654982.49 | U414: 8610557.2 | V414: 887937.78 | W414: 10.312199 | X414: 5907141.4 | Y414: 475592.43 | Z414: 1294231.1
A422: 43466

Sheet 5
A1: Workforce Jobs
B2: Workforce jobs | C2: Employee jobs | D2: Self-employment jobs | E2: HM Forces | F2: Government- supported trainees
A3: Current | B3: =INDEX(B$14:B$1048576,COUNT(B$14:B$1048576)) | C3: =INDEX(C$14:C$1048576,COUNT(C$14:C$1048576)) | D3: =INDEX(D$14:D$1048576,COUNT(D$14:D$1048576)) | E3: =INDEX(E$14:E$1048576,COUNT(E$14:E$1048576)) | F3: =INDEX(F$14:F$1048576,COUNT(F$14:F$1048576))
A4: Quarterly change | B4: =INDEX(B$14:B$1048576,COUNT(B$14:B$1048576))-INDEX(B$14:B$1048576,COUNT(B$14:B$1048576)-1) | C4: =INDEX(C$14:C$1048576,COUNT(C$14:C$1048576))-INDEX(C$14:C$1048576,COUNT(C$14:C$1048576)-1) | D4: =INDEX(D$14:D$1048576,COUNT(D$14:D$1048576))-INDEX(D$14:D$1048576,COUNT(D$14:D$1048576)-1) | E4: =INDEX(E$14:E$1048576,COUNT(E$14:E$1048576))-INDEX(E$14:E$1048576,COUNT(E$14:E$1048576)-1) | F4: =INDEX(F$14:F$1048576,COUNT(F$14:F$1048576))-INDEX(F$14:F$1048576,COUNT(F$14:F$1048576)-1)
A5: Max | B5: =MAX(B$14:B$1048576) | C5: =MAX(C$14:C$1048576) | D5: =MAX(D$14:D$1048576) | E5: =MAX(E$14:E$1048576) | F5: =MAX(F$14:F$1048576)
A6: Jobs created since new gov | B6: =INDEX(B$14:B$1048576,COUNT(B$14:B$1048576))-B$274 | C6: =INDEX(C$14:C$1048576,COUNT(C$14:C$1048576))-C$274 | D6: =INDEX(D$14:D$1048576,COUNT(D$14:D$1048576))-D$274 | E6: =INDEX(E$14:E$1048576,COUNT(E$14:E$1048576))-E$274 | F6: =INDEX(F$14:F$1048576,COUNT(F$14:F$1048576))-F$274
A7: Date of publication: | C7: 46100 | E7: Date of next publication: | F7: 46191
A8: Inquiries: Email: | C8: workforce.jobs@ons.gov.uk | E8: Telephone: | F8: 01633 455400
F9: Sources: Employer surveys, Labour Force Survey and administrative sources
A10: United Kingdom (thousands) seasonally adjusted
B11: Workforce jobs1 | C11: Employee jobs1 | D11: Self-employment jobs2 | E11: HM Forces | F11: Government- supported trainees2 3
B12: 1 | C12: 2 | D12: 3 | E12: 4 | F12: 5
B13: DYDC | C13: BCAJ | D13: DYZN | E13: LOJX | F13: LOJU
A14: Jun 59 | B14: 25555 | C14: 23125 | D14: 1835 | E14: 595 | F14: 0
A15: Sep 59 | B15: 25660 | C15: 23248 | D15: 1834 | E15: 577 | F15: 0
A16: Dec 59 | B16: 25751 | C16: 23370 | D16: 1820 | E16: 560 | F16: 0
A17: Mar 60 | B17: 25905 | C17: 23531 | D17: 1824 | E17: 550 | F17: 0
A18: Jun 60 | B18: 26015 | C18: 23634 | D18: 1840 | E18: 541 | F18: 0
A19: Sep 60 | B19: 26060 | C19: 23685 | D19: 1839 | E19: 536 | F19: 0
A20: Dec 60 | B20: 26246 | C20: 23894 | D20: 1827 | E20: 526 | F20: 0
A21: Mar 61 | B21: 26345 | C21: 24011 | D21: 1827 | E21: 507 | F21: 0
A22: Jun 61 | B22: 26312 | C22: 23985 | D22: 1832 | E22: 495 | F22: 0
A23: Sep 61 | B23: 26374 | C23: 24065 | D23: 1824 | E23: 485 | F23: 0
A24: Dec 61 | B24: 26301 | C24: 24014 | D24: 1812 | E24: 475 | F24: 0
A25: Mar 62 | B25: 26450 | C25: 24175 | D25: 1809 | E25: 466 | F25: 0
... A280: Dec 25 (p) | B280: 36563 | C280: 32323 | D280: 4037 | E280: 148 | F280: 54

Sheet 10
A1: Redundancies
B2: People | D2: Men | F2: Women
B3: Level | C3: Rate per thousand | D3: Level | E3: Rate per thousand | F3: Level | G3: Rate per thousand
A4: Current | B4: =B$423 | C4: =C$423 | D4: =D$423 | E4: =E$423 | F4: =F$423 | G4: =G$423
A5: Quarterly change | B5: =B$423-B$420 | C5: =C$423-C$420 | D5: =D$423-D$420 | E5: =E$423-E$420 | F5: =F$423-F$420 | G5: =G$423-G$420
A6: year on year change | B6: =B$423-B$411 | C6: =C$423-C$411 | D6: =D$423-D$411 | E6: =E$423-E$411 | F6: =F$423-F$411 | G6: =G$423-G$411
A7: Since pandemic | B7: =B$423-B$351 | C7: =C$423-C$351 | D7: =D$423-D$351 | E7: =E$423-E$351 | F7: =F$423-F$351 | G7: =G$423-G$351
A8: Since 2010 election | B8: =B$423-B$233 | C8: =C$423-C$233 | D8: =D$423-D$233 | E8: =E$423-E$233 | F8: =F$423-F$233 | G8: =G$423-G$233
A10: Date of publication: | B10: 46133 | F10: Date of next publication: | G10: 46161
A11: Inquiries: Email: | B11: labour.market@ons.gov.uk | F11: Telephone: | G11: 01633 455400
A12: United Kingdom (thousands)
B13: People | D13: Men | F13: Women
B15: Level1 | C15: Rate per thousand2 | D15: Level1 | E15: Rate per thousand2 | F15: Level1 | G15: Rate per thousand2
A16: Dataset identifier code | B16: BEAO | C16: BEIR | D16: BEIU | E16: BEIX | F16: BEJA | G16: BEJD
A18: Mar-May 1992 | B18: .. | C18: .. | D18: .. | E18: .. | F18: .. | G18: ..
A19: Apr-Jun 1992 | B19: .. | C19: .. | D19: .. | E19: .. | F19: .. | G19: ..
A20: May-Jul 1992 | B20: .. | C20: .. | D20: .. | E20: .. | F20: .. | G20: ..
A21: Jun-Aug 1992 | B21: .. | C21: .. | D21: .. | E21: .. | F21: .. | G21: ..
A22: Jul-Sep 1992 | B22: .. | C22: .. | D22: .. | E22: .. | F22: .. | G22: ..
A23: Aug-Oct 1992 | B23: .. | C23: .. | D23: .. | E23: .. | F23: .. | G23: ..
A24: Sep-Nov 1992 | B24: .. | C24: .. | D24: .. | E24: .. | F24: .. | G24: ..
A25: Oct-Dec 1992 | B25: .. | C25: .. | D25: .. | E25: .. | F25: .. | G25: ..
A26: Nov-Jan 1993 | B26: .. | C26: .. | D26: .. | E26: .. | F26: .. | G26: ..
A27: Dec-Feb 1993 | B27: .. | C27: .. | D27: .. | E27: .. | F27: .. | G27: ..
A28: Jan-Mar 1993 | B28: .. | C28: .. | D28: .. | E28: .. | F28: .. | G28: ..
... A53: Feb-Apr 1995 | B53: .. | C53: .. | D53: .. | E53: .. | F53: .. | G53: ..
A54: Mar-May 1995 | B54: 178580 | C54: 8.251544 | D54: 110631 | E54: 9.9189782 | F54: 67949 | G54: 6.4784023
A55: Apr-Jun 1995 | B55: 178249 | C55: 8.2250899 | D55: 109540 | E55: 9.8141913 | F55: 68709 | G55: 6.5374969
A56: May-Jul 1995 | B56: 168000 | C56: 7.7329073 | D56: 103867 | E56: 9.2790908 | F56: 64133 | G56: 6.0895355
A57: Jun-Aug 1995 | B57: 163905 | C57: 7.5347454 | D57: 104365 | E57: 9.2990437 | F57: 59540 | G57: 5.6543068
A58: Jul-Sep 1995 | B58: 164420 | C58: 7.5466264 | D58: 105296 | E58: 9.3726495 | F58: 59124 | G58: 5.6026685
A59: Aug-Oct 1995 | B59: 166301 | C59: 7.614352 | D59: 109483 | E59: 9.7290985 | F59: 56818 | G59: 5.3666099
A60: Sep-Nov 1995 | B60: 172777 | C60: 7.8856048 | D60: 110607 | E60: 9.7931999 | F60: 62170 | G60: 5.8561635
A61: Oct-Dec 1995 | B61: 162067 | C61: 7.3918845 | D61: 105156 | E61: 9.3096925 | F61: 56911 | G61: 5.353978
A62: Nov-Jan 1996 | B62: 179069 | C62: 8.1652749 | D62: 118724 | E62: 10.525961 | F62: 60345 | G62: 5.6654558
A63: Dec-Feb 1996 | B63: 181867 | C63: 8.2774116 | D63: 119522 | E63: 10.572536 | F63: 62345 | G63: 5.8449181
A64: Jan-Mar 1996 | B64: 195674 | C64: 8.866101 | D64: 130879 | E64: 11.520213 | F64: 64795 | G64: 6.0504675
A65: Feb-Apr 1996 | B65: 180895 | C65: 8.1844071 | D65: 118927 | E65: 10.471299 | F65: 61968 | G65: 5.7671641
... A423: Dec-Feb 2026 | B423: 136361 | C423: 4.5866316 | D423: 71145 | E423: 4.8314924 | F423: 65216 | G423: 4.346333

Sheet 11
C1: Economic inactivity by reason (thousands) | M1: Percentage of economically inactive (%)
B2: Total economically inactive aged 16-64 (thousands)4 | C2: Student | D2: Looking after family / home | E2: Temp sick | F2: Long-term sick | G2: Discouraged workers1 | H2: Retired | I2: Other2 | J2: Does not want job (thousands) | K2: Wants a job (thousands) | L2: Total economically inactive aged 16-64 | M2: Student | N2: Looking after family / home | O2: Temp sick | P2: Long-term sick | Q2: Discouraged workers1 | R2: Retired | S2: Other2 | T2: Does not want job (%age of economically inactive) | U2: Wants a job (%age of economically inactive)
A3: Current | B3: =B$422 | C3: =C$422 | D3: =D$422 | E3: =E$422 | F3: =F$422 | G3: =G$422 | H3: =H$422 | I3: =I$422 | ... U3: =U$422
A4: Quarterly change | B4: =B$422-B$419 | C4: =C$422-C$419 | D4: =D$422-D$419 | E4: =E$422-E$419 | F4: =F$422-F$419 | G4: =G$422-G$419 | H4: =H$422-H$419 | I4: =I$422-I$419 | ... U4: =U$422-U$419
A5: year on year change | B5: =B$422-B$410 | C5: =C$422-C$410 | D5: =D$422-D$410 | E5: =E$422-E$410 | F5: =F$422-F$410 | G5: =G$422-G$410 | H5: =H$422-H$410 | I5: =I$422-I$410 | ... U5: =U$422-U$410
A6: Since pandemic | B6: =B$422-B$350 | C6: =C$422-C$350 | D6: =D$422-D$350 | E6: =E$422-E$350 | F6: =F$422-F$350 | G6: =G$422-G$350 | H6: =H$422-H$350 | I6: =I$422-I$350 | ... U6: =U$422-U$350
A7: Since 2010 election | B7: =B$422-B$232 | C7: =C$422-C$232 | D7: =D$422-D$232 | E7: =E$422-E$232 | F7: =F$422-F$232 | G7: =G$422-G$232 | H7: =H$422-H$232 | I7: =I$422-I$232 | ... U7: =U$422-U$232
A9: Date of publication: | B9: 46133 | G9: Date of next publication: | I9: 46161
A10: Inquiries: Email: | B10: labour.market@ons.gov.uk | H10: Telephone: | I10: 01633 455400 | AW10: Source: Labour Force Survey
A11: United Kingdom (thousands) seasonally adjusted
C12: Economic inactivity by reason (thousands) | M12: Percentage of economically inactive (%) | W12: Economic inactivity by wants a job (thousands) | AD12: Percentage of economically inactive by wants a job (%) | AK12: Economic inactivity by does not want a job (thousands) | AR12: Percentage of economically inactive by does not want a job (%)
B13: Total economically inactive aged 16-64 (thousands)4 | C13: Student | D13: Looking after family / home | E13: Temp sick | F13: Long-term sick | G13: Discouraged workers1 | H13: Retired | I13: Other2 | J13: Does not want job (thousands) | K13: Wants a job (thousands) | L13: Total economically inactive aged 16-64 | M13: Student | N13: Looking after family / home | O13: Temp sick | P13: Long-term sick | Q13: Discouraged workers1 | R13: Retired | S13: Other2 | T13: Does not want job (%age of economically inactive) | U13: Wants a job (%age of economically inactive) | V13: Total economically inactive wants a job aged 16-64 (thousands) | W13: Student | X13: Looking after family / home | Y13: Temp sick | Z13: Long-term sick | AA13: Discouraged workers1 | AB13: Other2 | AC13: Total wants a job aged 16-64 | AD13: Student | AE13: Looking after family / home | AF13: Temp sick | AG13: Long-term sick | AH13: Discouraged workers1 | AI13: Other2 | AJ13: Total economically inactive does not want a job aged 16-64 (thousands) | AK13: Student | AL13: Looking after family / home | AM13: Temp sick | AN13: Long-term sick | AO13: Retired | AP13: Other2 | AQ13: Total does not want a job aged 16-64 | AR13: Student | AS13: Looking after family / home | AT13: Temp sick | AU13: Long-term sick | AV13: Retired | AW13: Other2
